Workbook

Sheet Halfling A
A1: Giocatore | B1: Azzeil Summerhill | G1: Agile Furtivo Preciso | K1: Esperienza | N1: 30.000
A2: Razza | B2: Halfling | E2: Classe | G2: Halfling | I2: 5° | K2: Allineamento | N2: Neutrale
A4: CA | B4: 3 | D4: Peso | F4: 20 | G4: +6 | K4: Iniziativa | M4: 2 | O4: PF | P4: 25
A5: Abilità | J5: Mod. | M5: Tiri salvezza
A6: 14 | B6: FOR | C6: Apre porte bloccate con 1-3 su 1d6 | J6: 1 | M6: Veleno, Raggio della Morte, +1 mg | P6: 6
A7: 14 | B7: DES | C7: Bonus a attacchi a distanza, CA, iniziativa | J7: 1 | M7: Bacchetta | P7: 7
A8: 9 | B8: COS | C8: Nessun modificatore | J8: 0 | M8: Pietrificazione Paralisi | P8: 8
A9: 13 | B9: INT | C9: Legge e scrive più lingue | J9: 1 | M9: Soffio Drago | P9: 10
A10: 12 | B10: SAG | C10: Nessun modificatore | J10: 0 | M10: Incantesimi Bastone Magico | P10: 10
A11: 11 | B11: CAR | C11: Reazioni PNG +0, massimo 4 seguaci, morale seguaci 7 | J11: 0
A13: Lingue Parlate | E13: Movimento | I13: Piedi | J13: Metri | K13: Quad. | N13: Slot/Equipaggiamento
A14: Common, Nanco, Gnomesco, Koboldo,Goblin | E14: Combattimento | H14: 1R | I14: 20 | J14: =K14*1.5 -> 6 | K14: =I14/5 -> 4 | N14: 2/Cotta di maglia
E15: Esplorazione | H15: 1T | I15: =I14*3 -> 60 | J15: =K15*1.5 -> 18 | K15: =I15/5 -> 12 | N15: 1/Pugnali (2)
E16: Correre | H16: 1R | I16: =I14*3 -> 60 | J16: =K16*1.5 -> 18 | K16: =I16/5 -> 12 | N16: 1/Sacchetto Pietre
A17: THAC0 - Tiro = CA Colpita | E17: Arrampicarsi | H17: 1R | I17: =I14/2 -> 10 | J17: =K17*1.5 -> 3 | K17: =I17/5 -> 2 | N17: 0/Vestiti, Cintura, Stivali
A18: 1R = 10 Sec. | 1T = 10 Min. | E18: Nuotare | H18: 1R | I18: =I14/2 -> 10 | J18: =K18*1.5 -> 3 | K18: =I18/5 -> 2 | N18: 1/Fionda
E19: Giornaliero | H19: 1G | I19: 12mi | J19: 19km | N19: 1/Spada Corta
A20: Freccie | N20: 2/Scudo
A21: Quadrelli | E21: ='Cleric A'!E21 -> Carica, Ritirata difensiva, Difesa totale
A22: Pietre | E22: ='Cleric A'!E22 -> Spinta, Disarmo, Parare (F), Colpo potente (F) | O22: Slot | P22: 8
A23: Dardi | E23: ='Cleric A'!E23 -> Afferrrare, Liberarsi da presa, Azione Pronta
A24: Giavellotti | E24: ='Cleric A'!E24 -> Attraversare alleati ©, Passare posizione © , | O24: Banca | P24: Trasportati
A25: Olio | E25: ='Cleric A'!E25 -> Azione pronta, Preparare per carica | N25: pp
A26: Acqua Santa | E26: ='Cleric A'!E26 -> Prone: +2 TxC nemici, metà mov per alzarsi | N26: mo | P26: 500
A27: Torce | E27: ='Cleric A'!E27 -> Copertura: Parziale -2 TxC | Totale -4 TxC | N27: ma
E28: ='Cleric A'!E28 -> Tiro oltre 1* alleato: -2 TxC, 1 Colpito Alleato | N28: mr
E29: ='Cleric A'!E29 -> Distanza: corta +1, lunga -1 | O29: Slot | P29: 5
E30: ='Cleric A'!E30 -> Copertura vs area: Parz. +2 TS, Quasi tot. +4 TS
N32: Abilità
A33: Halfling vs Nemici Grandi: +2 CA contro creature più grandi di un umano | N33: 1/6 trovare porte segrete
A34: All'aperto (boschi/sottobosco): 90% di non essere individuato | N34: 2/6 Ascoltare rumori
A35: In dungeon (ombre, fermo e silenzioso): 1-2 su 1d6 di non essere visto | N35: 1/6 ascoltare attr. Porte
L36: THAC0
A37: Arma | B37: Range | C37: AC 9 | D37: 8 | E37: =D37-1 -> 7 | F37: =E37-1 -> 6 | G37: =F37-1 -> 5 | H37: =G37-1 -> 4 | I37: =H37-1 -> 3 | J37: =I37-1 -> 2 | K37: =J37-1 -> 1 | L37: =K37-1 -> 0 | M37: Danno | O37: Note
A38: Spada Corta | B38: melee | C38: 7 | D38: =C38+1 -> 8 | E38: =D38+1 -> 9 | F38: =E38+1 -> 10 | G38: =F38+1 -> 11 | H38: =G38+1 -> 12 | I38: =H38+1 -> 13 | J38: =I38+1 -> 14 | K38: =J38+1 -> 15 | L38: =K38+1 -> 16 | M38: 1d6+1
A39: Pugnale | B39: melee | C39: 7 | D39: =C39+1 -> 8 | E39: =D39+1 -> 9 | F39: =E39+1 -> 10 | G39: =F39+1 -> 11 | H39: =G39+1 -> 12 | I39: =H39+1 -> 13 | J39: =I39+1 -> 14 | K39: =J39+1 -> 15 | L39: =K39+1 -> 16 | M39: 1d4+1 | O39: lanciabile 10/20/30'
A40: Fionda | B40: 40/80/160' | C40: 6 | D40: =C40+1 -> 7 | E40: =D40+1 -> 8 | F40: =E40+1 -> 9 | G40: =F40+1 -> 10 | H40: =G40+1 -> 11 | I40: =H40+1 -> 12 | J40: =I40+1 -> 13 | K40: =J40+1 -> 14 | L40: =K40+1 -> 15 | M40: 1d4 | O40: 12 pietre

Sheet Elfo A
A1: Giocatore | B1: Conno Darhov | G1: Guerriero Arcano Versatile | K1: Esperienza | N1: 33,650
A2: Razza | B2: Elfo | E2: Classe | G2: Elfo | I2: 5° | K2: Allineamento | N2: Neutrale
A4: CA | B4: 4 | D4: Peso | F4: 24 | G4: +8 | K4: Iniziativa | M4: 0 | O4: PF | P4: 30
A5: Abilità | J5: Mod. | M5: Tiri salvezza
A6: 16 | B6: FOR | C6: Apre porte bloccate con 1-4 su 1d6 | J6: 2 | M6: Veleno, Raggio della Morte, +1 mg | P6: 10
A7: 12 | B7: DES | C7: Nessun modificatore | J7: 0 | M7: Bacchetta | P7: 11
A8: 13 | B8: COS | C8: Bonus punti ferita aggiunti al totale | J8: 1 | M8: Pietrificazione Paralisi | P8: 11
A9: 17 | B9: INT | C9: Legge e scrive più lingue | J9: 2 | M9: Soffio Drago | P9: 13
A10: 11 | B10: SAG | C10: Nessun modificatore | J10: 0 | M10: Incantesimi Bastone Magico | P10: 12
A11: 10 | B11: CAR | C11: Reazioni PNG +0, massimo 4 seguaci, morale seguaci 7 | J11: 0
A13: Lingue Parlate | E13: Movimento | I13: Piedi | J13: Metri | K13: Quad. | N13: Slot/Equipaggiamento
A14: Common, Nanco, Gnomesco, Koboldo,Goblin | E14: Combattimento | H14: 1R | I14: 30 | J14: =K14*1.5 -> 9 | K14: =I14/5 -> 6 | N14: 2/Cotta di maglia
E15: Esplorazione | H15: 1T | I15: =I14*3 -> 90 | J15: =K15*1.5 -> 27 | K15: =I15/5 -> 18 | N15: 1/Pugnali (2)
E16: Correre | H16: 1R | I16: =I14*3 -> 90 | J16: =K16*1.5 -> 27 | K16: =I16/5 -> 18 | N16: 2/Spada
A17: THAC0 - Tiro = CA Colpita | E17: Arrampicarsi | H17: 1R | I17: =I14/2 -> 15 | J17: =K17*1.5 -> 4.5 | K17: =I17/5 -> 3 | N17: 3/Arco Lungo
A18: 1R = 10 Sec. | 1T = 10 Min. | E18: Nuotare | H18: 1R | I18: =I14/2 -> 15 | J18: =K18*1.5 -> 4.5 | K18: =I18/5 -> 3 | N18: 0/Vestiti, Cintura, Stivali
E19: Giornaliero | H19: 1G | I19: 18mi | J19: 29km | N19: 1/Libro Incantesimi
A20: Freccie | N20: 1/Faretra
A21: Quadrelli | E21: ='Cleric A'!E21 -> Carica, Ritirata difensiva, Difesa totale | N21: 2/Scudo
A22: Pietre | E22: ='Cleric A'!E22 -> Spinta, Disarmo, Parare (F), Colpo potente (F) | O22: Slot | P22: 12
A23: Dardi | E23: ='Cleric A'!E23 -> Afferrrare, Liberarsi da presa, Azione Pronta
A24: Giavellotti | E24: ='Cleric A'!E24 -> Attraversare alleati ©, Passare posizione © , | O24: Banca | P24: Trasportati
A25: Olio | E25: ='Cleric A'!E25 -> Azione pronta, Preparare per carica | N25: pp
A26: Acqua Santa | E26: ='Cleric A'!E26 -> Prone: +2 TxC nemici, metà mov per alzarsi | N26: mo | P26: 500
A27: Torce | E27: ='Cleric A'!E27 -> Copertura: Parziale -2 TxC | Totale -4 TxC | N27: ma
E28: ='Cleric A'!E28 -> Tiro oltre 1* alleato: -2 TxC, 1 Colpito Alleato | N28: mr
E29: ='Cleric A'!E29 -> Distanza: corta +1, lunga -1 | O29: Slot | P29: 5
E30: ='Cleric A'!E30 -> Copertura vs area: Parz. +2 TS, Quasi tot. +4 TS
A31: Incantesimi Scelti | C31: 1°/2 | E31: 2°/2 | G31: 3°/1 | N31: Abilità
A32: 1 Livello | B32: Dardo Incantato 2d6+2 150' x 2 | N32: 2/6 trovare porte segrete
A33: 2 Livello | B33: Immagine Speculare 1d4 6T, Scassinare 60' | N33: 1/6 Ascoltare rumori
A34: 3 Livello | B34: Fulmine 5d6 60'x5' | N34: 2/6 ascoltare attr. Porte
N35: Immune paralisi Ghoul
L36: THAC0
A37: Arma | B37: Range | C37: AC 9 | D37: 8 | E37: =D37-1 -> 7 | F37: =E37-1 -> 6 | G37: =F37-1 -> 5 | H37: =G37-1 -> 4 | I37: =H37-1 -> 3 | J37: =I37-1 -> 2 | K37: =J37-1 -> 1 | L37: =K37-1 -> 0 | M37: Danno | O37: Note
A38: Spada | B38: melee | C38: 6 | D38: =C38+1 -> 7 | E38: =D38+1 -> 8 | F38: =E38+1 -> 9 | G38: =F38+1 -> 10 | H38: =G38+1 -> 11 | I38: =H38+1 -> 12 | J38: =I38+1 -> 13 | K38: =J38+1 -> 14 | L38: =K38+1 -> 15 | M38: 1d8+2
A39: Pugnale | B39: melee | C39: 6 | D39: =C39+1 -> 7 | E39: =D39+1 -> 8 | F39: =E39+1 -> 9 | G39: =F39+1 -> 10 | H39: =G39+1 -> 11 | I39: =H39+1 -> 12 | J39: =I39+1 -> 13 | K39: =J39+1 -> 14 | L39: =K39+1 -> 15 | M39: 1d4+2
A40: Arco Lungo | B40: 70/140/210' | C40: 8 | D40: =C40+1 -> 9 | E40: =D40+1 -> 10 | F40: =E40+1 -> 11 | G40: =F40+1 -> 12 | H40: =G40+1 -> 13 | I40: =H40+1 -> 14 | J40: =I40+1 -> 15 | K40: =J40+1 -> 16 | L40: =K40+1 -> 17 | M40: 1d6

Sheet Nano A
A1: Giocatore | B1: Seska Poluth | G1: Nano Corazzato Resistente | K1: Esperienza | N1: 30.000
A2: Razza | B2: Nano | E2: Classe | G2: Nano | I2: 5° | K2: Allineamento | N2: Neutrale
A4: CA | B4: 2 | D4: Peso | F4: 22 | G4: +7 | K4: Iniziativa | M4: 0 | O4: PF | P4: 44
A5: Abilità | J5: Mod. | M5: Tiri salvezza
A6: 13 | B6: FOR | C6: Apre porte bloccate con 1-3 su 1d6 | J6: 1 | M6: Veleno, Raggio della Morte, +1 mg | P6: 6
A7: 10 | B7: DES | C7: Nessun modificatore | J7: 0 | M7: Bacchetta | P7: 6
A8: 16 | B8: COS | C8: Bonus punti ferita aggiunti al totale | J8: 2 | M8: Pietrificazione Paralisi | P8: 7
A9: 10 | B9: INT | C9: Legge e scrive nella lingua nativa | J9: 0 | M9: Soffio Drago | P9: 10
A10: 13 | B10: SAG | C10: Bonus ai TS contro magia | J10: 1 | M10: Incantesimi Bastone Magico | P10: 9
A11: 11 | B11: CAR | C11: Reazioni PNG +0, massimo 4 seguaci, morale seguaci 7 | J11: 0
A13: Lingue Parlate | E13: Movimento | I13: Piedi | J13: Metri | K13: Quad. | N13: Slot/Equipaggiamento
A14: Common, Nanco, Gnomesco, Koboldo,Goblin | E14: Combattimento | H14: 1R | I14: 20 | J14: =K14*1.5 -> 6 | K14: =I14/5 -> 4 | N14: 3/Armatura a piastre
E15: Esplorazione | H15: 1T | I15: 60 | J15: =K15*1.5 -> 18 | K15: =I15/5 -> 12 | N15: 1/Pugnali (2)
E16: Correre | H16: 1R | I16: 60 | J16: =K16*1.5 -> 18 | K16: =I16/5 -> 12 | N16: 2/Arco Corto
A17: THAC0 - Tiro = CA Colpita | E17: Arrampicarsi | H17: 1R | I17: 10 | J17: =K17*1.5 -> 3 | K17: =I17/5 -> 2 | N17: 0/Vestiti, Cintura, Stivali
A18: 1R = 10 Sec. | 1T = 10 Min. | E18: Nuotare | H18: 1R | I18: 10 | J18: =K18*1.5 -> 3 | K18: =I18/5 -> 2 | N18: 2/Ascia da Battaglia
E19: Giornaliero | H19: 1G | I19: 12 mi | J19: 19km | N19: 2/Scudo
A20: Freccie | N20: 1/Faretra
A21: Quadrelli | E21: ='Cleric A'!E21 -> Carica, Ritirata difensiva, Difesa totale
A22: Pietre | E22: ='Cleric A'!E22 -> Spinta, Disarmo, Parare (F), Colpo potente (F) | O22: Slot | P22: 11
A23: Dardi | E23: ='Cleric A'!E23 -> Afferrrare, Liberarsi da presa, Azione Pronta
A24: Giavellotti | E24: ='Cleric A'!E24 -> Attraversare alleati ©, Passare posizione © , | O24: Banca | P24: Trasportati
A25: Olio | E25: ='Cleric A'!E25 -> Azione pronta, Preparare per carica | N25: pp
A26: Acqua Santa | E26: ='Cleric A'!E26 -> Prone: +2 TxC nemici, metà mov per alzarsi | N26: mo | P26: 500
A27: Torce | E27: ='Cleric A'!E27 -> Copertura: Parziale -2 TxC | Totale -4 TxC | N27: ma
E28: ='Cleric A'!E28 -> Tiro oltre 1* alleato: -2 TxC, 1 Colpito Alleato | N28: mr
E29: ='Cleric A'!E29 -> Distanza: corta +1, lunga -1 | O29: Slot | P29: 5
E30: ='Cleric A'!E30 -> Copertura vs area: Parz. +2 TS, Quasi tot. +4 TS
A31: Combinazioni | C31: CA | N31: Abilità
A32: Ascia/pugnale + Scudo | C32: 2 | N32: 1/6 trovare porte segrete
A33: Ascia due mani | C33: 3 | N33: 1/6 Ascoltare rumori
A34: Arco Corto | C34: 3 | N34: 1/6 ascoltare attr. Porte
A35: Pugnale | C35: 3 | N35: Infravsione 60'/12q
L36: THAC0
A37: Arma | B37: Range | C37: AC 9 | D37: 8 | E37: =D37-1 -> 7 | F37: =E37-1 -> 6 | G37: =F37-1 -> 5 | H37: =G37-1 -> 4 | I37: =H37-1 -> 3 | J37: =I37-1 -> 2 | K37: =J37-1 -> 1 | L37: =K37-1 -> 0 | M37: Danno | O37: Note
A38: Ascia da B. | B38: melee lenta | C38: 7 | D38: =C38+1 -> 8 | E38: =D38+1 -> 9 | F38: =E38+1 -> 10 | G38: =F38+1 -> 11 | H38: =G38+1 -> 12 | I38: =H38+1 -> 13 | J38: =I38+1 -> 14 | K38: =J38+1 -> 15 | L38: =K38+1 -> 16 | M38: 1d8+1 | O38: 1 mano 1d6+1
A39: Pugnale | B39: melee | C39: 7 | D39: =C39+1 -> 8 | E39: =D39+1 -> 9 | F39: =E39+1 -> 10 | G39: =F39+1 -> 11 | H39: =G39+1 -> 12 | I39: =H39+1 -> 13 | J39: =I39+1 -> 14 | K39: =J39+1 -> 15 | L39: =K39+1 -> 16 | M39: 1d4+1 | O39: lanciabile 10/20/30'
A40: Arco Corto | B40: 50/100/150 | C40: 8 | D40: =C40+1 -> 9 | E40: =D40+1 -> 10 | F40: =E40+1 -> 11 | G40: =F40+1 -> 12 | H40: =G40+1 -> 13 | I40: =H40+1 -> 14 | J40: =I40+1 -> 15 | K40: =J40+1 -> 16 | L40: =K40+1 -> 17 | M40: 1d6 | O40: 12 freccie

Sheet Ladro A
A1: Giocatore | B1: Cesaire Thorn | G1: Agile Furtivo Preciso | K1: Esperienza | N1: 30.000
A2: Razza | B2: Umano | E2: Classe | G2: Ladro | I2: 6° | K2: Allineamento | N2: Neutrale
A4: CA | B4: 4 | D4: Peso | F4: 20 | G4: +6 | K4: Iniziativa | M4: 2 | O4: PF | P4: 26
A5: Abilità | J5: Mod. | M5: Tiri salvezza
A6: 9 | B6: FOR | C6: Apre porte bloccate con 1-2 su 1d6 | J6: 0 | M6: Veleno, Raggio della Morte, +1 mg | P6: 12
A7: 16 | B7: DES | C7: Bonus a attacchi a distanza, CA, iniziativa | J7: 2 | M7: Bacchetta | P7: 14
A8: 13 | B8: COS | C8: Bonus punti ferita aggiunti al totale | J8: 1 | M8: Pietrificazione Paralisi | P8: 12
A9: 14 | B9: INT | C9: Legge e scrive più lingue | J9: 1 | M9: Soffio Drago | P9: 16
A10: 6 | B10: SAG | C10: Penalità ai TS contro magia | J10: -1 | M10: Incantesimi Bastone Magico | P10: 14
A11: 10 | B11: CAR | C11: Reazioni PNG +0, massimo 4 seguaci, morale seguaci 7 | J11: 0
A13: Lingue Parlate | E13: Movimento | I13: Piedi | J13: Metri | K13: Quad. | N13: Slot/Equipaggiamento
A14: Common, Nanco, Gnomesco, Koboldo,Goblin | E14: Combattimento | H14: 1R | I14: 40 | J14: =K14*1.5 -> 12 | K14: =I14/5 -> 8 | N14: 2/Armatura di cuoio +1
E15: Esplorazione | H15: 1T | I15: =I14*3 -> 120 | J15: =K15*1.5 -> 36 | K15: =I15/5 -> 24 | N15: 1/Pugnali (2)
E16: Correre | H16: 1R | I16: =I14*3 -> 120 | J16: =K16*1.5 -> 36 | K16: =I16/5 -> 24 | N16: 2/Arco Corto
A17: THAC0 - Tiro = CA Colpita | E17: Arrampicarsi | H17: 1R | I17: =I14/2 -> 20 | J17: =K17*1.5 -> 6 | K17: =I17/5 -> 4 | N17: 0/Vestiti, Cintura, Stivali
A18: 1R = 10 Sec. | 1T = 10 Min. | E18: Nuotare | H18: 1R | I18: =I14/2 -> 20 | J18: =K18*1.5 -> 6 | K18: =I18/5 -> 4 | N18: 1/Atrezzi da scasso
E19: Giornaliero | H19: 1G | I19: 24mi | J19: 38km | N19: 2/Spada
A20: Freccie | N20: 1/Faretra
A21: Quadrelli | E21: ='Cleric A'!E21 -> Carica, Ritirata difensiva, Difesa totale
A22: Pietre | E22: ='Cleric A'!E22 -> Spinta, Disarmo, Parare (F), Colpo potente (F) | O22: Slot | P22: 9
A23: Dardi | E23: ='Cleric A'!E23 -> Afferrrare, Liberarsi da presa, Azione Pronta
A24: Giavellotti | E24: ='Cleric A'!E24 -> Attraversare alleati ©, Passare posizione © , | O24: Banca | P24: Trasportati
A25: Olio | E25: ='Cleric A'!E25 -> Azione pronta, Preparare per carica | N25: pp
A26: Acqua Santa | E26: ='Cleric A'!E26 -> Prone: +2 TxC nemici, metà mov per alzarsi | N26: mo | P26: 500
A27: Torce | E27: ='Cleric A'!E27 -> Copertura: Parziale -2 TxC | Totale -4 TxC | N27: ma
E28: ='Cleric A'!E28 -> Tiro oltre 1* alleato: -2 TxC, 1 Colpito Alleato | N28: mr
A29: Scassinare | C29: 0.45 | E29: ='Cleric A'!E29 -> Distanza: corta +1, lunga -1 | O29: Slot | P29: 5
A30: Trov./Rim. Trappole | C30: 0.4 | E30: ='Cleric A'!E30 -> Copertura vs area: Parz. +2 TS, Quasi tot. +4 TS
A31: Borseggiare | C31: 0.45
A32: Muoversi Silenziosamente | C32: 0.45 | N32: Abilità
A33: Scalare Parti Lisce | C33: 0.92 | N33: 1/6 trovare porte segrete
A34: Nascondersi nelle Ombre | C34: 0.36 | N34: 3/6 Ascoltare rumori
A35: Leg. Lingue non Magiche | C35: 0.8 | E35: Attacco alle Spalle +4 TxC, Danno x 2 | N35: 3/6 ascoltare attr. Porte
L36: THAC0
A37: Arma | B37: Range | C37: AC 9 | D37: 8 | E37: =D37-1 -> 7 | F37: =E37-1 -> 6 | G37: =F37-1 -> 5 | H37: =G37-1 -> 4 | I37: =H37-1 -> 3 | J37: =I37-1 -> 2 | K37: =J37-1 -> 1 | L37: =K37-1 -> 0 | M37: Danno | O37: Note
A38: Spada | B38: melee | C38: 8 | D38: =C38+1 -> 9 | E38: =D38+1 -> 10 | F38: =E38+1 -> 11 | G38: =F38+1 -> 12 | H38: =G38+1 -> 13 | I38: =H38+1 -> 14 | J38: =I38+1 -> 15 | K38: =J38+1 -> 16 | L38: =K38+1 -> 17 | M38: 1d8
A39: Pugnale | B39: melee | C39: 8 | D39: =C39+1 -> 9 | E39: =D39+1 -> 10 | F39: =E39+1 -> 11 | G39: =F39+1 -> 12 | H39: =G39+1 -> 13 | I39: =H39+1 -> 14 | J39: =I39+1 -> 15 | K39: =J39+1 -> 16 | L39: =K39+1 -> 17 | M39: 1d4 | O39: lanciabile 10/20/30'
A40: Arco Corto | B40: 50/100/150' | C40: 6 | D40: =C40+1 -> 7 | E40: =D40+1 -> 8 | F40: =E40+1 -> 9 | G40: =F40+1 -> 10 | H40: =G40+1 -> 11 | I40: =H40+1 -> 12 | J40: =I40+1 -> 13 | K40: =J40+1 -> 14 | L40: =K40+1 -> 15 | M40: 1d6 | O40: 12 freccie

Sheet Magic A
A1: Giocatore | B1: Juven Lionsbane | G1: Fragile Arcano Potente | K1: Esperienza | N1: 30.000
A2: Razza | B2: Umano | E2: Classe | G2: Mago | I2: 5° | K2: Allineamento | N2: Neutrale
A4: CA | B4: 9 | D4: Peso | F4: 18 | G4: 5 | K4: Iniziativa | M4: 0 | O4: PF | P4: 21
A5: Abilità | J5: Mod. | M5: Tiri salvezza
A6: 8 | B6: FOR | C6: Apre porte bloccate con 1 su 1d6 | J6: -1 | M6: Veleno, Raggio della Morte, +1 mg | P6: 13
A7: 10 | B7: DES | C7: Nessun modificatore | J7: 0 | M7: Bacchetta | P7: 14
A8: 13 | B8: COS | C8: Bonus punti ferita aggiunti al totale | J8: 1 | M8: Pietrificazione Paralisi | P8: 13
A9: 16 | B9: INT | C9: Legge e scrive più lingue | J9: 2 | M9: Soffio Drago | P9: 16
A10: 9 | B10: SAG | C10: Nessun modificatore | J10: 0 | M10: Incantesimi Bastone Magico | P10: 15
A11: 8 | B11: CAR | C11: Reazioni PNG -1, massimo 3 seguaci, morale seguaci 6 | J11: -1
A13: Lingue Parlate | E13: Movimento | I13: Piedi | J13: Metri | K13: Quad. | N13: Slot/Equipaggiamento
A14: Common, Nanco, Gnomesco, Koboldo,Goblin | E14: Combattimento | H14: 1R | I14: 40 | J14: =K14*1.5 -> 12 | K14: =I14/5 -> 8 | N14: 2/Bastone
E15: Esplorazione | H15: 1T | I15: =I14*3 -> 120 | J15: =K15*1.5 -> 36 | K15: =I15/5 -> 24 | N15: 1/Pugnali (2)
E16: Correre | H16: 1R | I16: =I14*3 -> 120 | J16: =K16*1.5 -> 36 | K16: =I16/5 -> 24 | N16: 0/Vestiti, Cintura, Stivali
A17: THAC0 - Tiro = CA Colpita | E17: Arrampicarsi | H17: 1R | I17: =I14/2 -> 20 | J17: =K17*1.5 -> 6 | K17: =I17/5 -> 4 | N17: 1/Libro Incantesimi
A18: 1R = 10 Sec. | 1T = 10 Min. | E18: Nuotare | H18: 1R | I18: =I14/2 -> 20 | J18: =K18*1.5 -> 6 | K18: =I18/5 -> 4
E19: Giornaliero | H19: 1G | I19: 24mi | J19: 38km
A20: Freccie
A21: Quadrelli | E21: ='Cleric A'!E21 -> Carica, Ritirata difensiva, Difesa totale
A22: Pietre | E22: ='Cleric A'!E22 -> Spinta, Disarmo, Parare (F), Colpo potente (F) | O22: Slot | P22: 4
A23: Dardi | E23: ='Cleric A'!E23 -> Afferrrare, Liberarsi da presa, Azione Pronta
A24: Giavellotti | E24: ='Cleric A'!E24 -> Attraversare alleati ©, Passare posizione © , | O24: Banca | P24: Trasportati
A25: Olio | E25: ='Cleric A'!E25 -> Azione pronta, Preparare per carica | N25: pp
A26: Acqua Santa | E26: ='Cleric A'!E26 -> Prone: +2 TxC nemici, metà mov per alzarsi | N26: mo | P26: 500
A27: Torce | E27: ='Cleric A'!E27 -> Copertura: Parziale -2 TxC | Totale -4 TxC | N27: ma
E28: ='Cleric A'!E28 -> Tiro oltre 1* alleato: -2 TxC, 1 Colpito Alleato | N28: mr
E29: ='Cleric A'!E29 -> Distanza: corta +1, lunga -1 | O29: Slot | P29: 5
E30: ='Cleric A'!E30 -> Copertura vs area: Parz. +2 TS, Quasi tot. +4 TS
A32: Incantesimi Scelti | C32: 1°/2 | E32: 2°/2 | G32: 3°/1 | N32: Abilità
A33: 1 Livello | B33: Dardo Incantato 2d6+2 150, Scudo CA2 | N33: 1/6 trovare porte segrete
A34: 2 Livello | B34: Immagine Speculare 1d4 6T, Levitare 11T | N34: 1/6 Ascoltare rumori
A35: 3 Livello | B35: Palla di Fuoco 5d6 240 | N35: 1/6 ascoltare attr. Porte
L36: THAC0
A37: Arma | B37: Range | C37: AC 9 | D37: 8 | E37: =D37-1 -> 7 | F37: =E37-1 -> 6 | G37: =F37-1 -> 5 | H37: =G37-1 -> 4 | I37: =H37-1 -> 3 | J37: =I37-1 -> 2 | K37: =J37-1 -> 1 | L37: =K37-1 -> 0 | M37: Danno | O37: Note
A38: Bastone | B38: melee | C38: 11 | D38: =C38+1 -> 12 | E38: =D38+1 -> 13 | F38: =E38+1 -> 14 | G38: =F38+1 -> 15 | H38: =G38+1 -> 16 | I38: =H38+1 -> 17 | J38: =I38+1 -> 18 | K38: =J38+1 -> 19 | L38: =K38+1 -> 20 | M38: 1d4-1
A39: Pugnale | B39: melee | C39: 11 | D39: =C39+1 -> 12 | E39: =D39+1 -> 13 | F39: =E39+1 -> 14 | G39: =F39+1 -> 15 | H39: =G39+1 -> 16 | I39: =H39+1 -> 17 | J39: =I39+1 -> 18 | K39: =J39+1 -> 19 | L39: =K39+1 -> 20 | M39: 1d4-1
A40: Pugnale | B40: 10/20/30' | C40: 10 | D40: =C40+1 -> 11 | E40: =D40+1 -> 12 | F40: =E40+1 -> 13 | G40: =F40+1 -> 14 | H40: =G40+1 -> 15 | I40: =H40+1 -> 16 | J40: =I40+1 -> 17 | K40: =J40+1 -> 18 | L40: =K40+1 -> 19 | M40: 1d4

Sheet Fighter A
A1: Giocatore | B1: Melisizwe Jeighmoor | G1: Guerriero Corazzato Arciere | K1: Esperienza | N1: 30.000
A2: Razza | B2: Umano | E2: Classe | G2: Guerriero | I2: 5° | K2: Allineamento | N2: Neutrale
A4: CA | B4: 0 | D4: Peso | F4: 24 | G4: +8 | K4: Iniziativa | M4: 1 | O4: PF | P4: 35
A5: Abilità | J5: Mod. | M5: Tiri salvezza
A6: 17 | B6: FOR | C6: Apre porte bloccate con 1-4 su 1d6 | J6: 2 | M6: Veleno, Raggio della Morte, +1 mg | P6: 10
A7: 14 | B7: DES | C7: Bonus a attacchi a distanza, CA, iniziativa | J7: 1 | M7: Bacchetta | P7: 13
A8: 11 | B8: COS | C8: Nessun modificatore | J8: 0 | M8: Pietrificazione Paralisi | P8: 14
A9: 7 | B9: INT | C9: Sa scrivere parole semplici | J9: -1 | M9: Soffio Drago | P9: 13
A10: 4 | B10: SAG | C10: Penalità ai TS contro magia | J10: -2 | M10: Incantesimi Bastone Magico | P10: 16
A11: 10 | B11: CAR | C11: Reazioni PNG +0, massimo 4 seguaci, morale seguaci 7 | J11: 0
A13: Lingue Parlate | E13: Movimento | I13: Piedi | J13: Metri | K13: Quad. | N13: Slot/Equipaggiamento
A14: Common, Nanco, Gnomesco, Koboldo,Goblin | E14: Combattimento | H14: 1R | I14: 20 | J14: =K14*1.5 -> 6 | K14: =I14/5 -> 4 | N14: 3/Armatura a piastre
E15: Esplorazione | H15: 1T | I15: 60 | J15: =K15*1.5 -> 18 | K15: =I15/5 -> 12 | N15: 1/Pugnali
E16: Correre | H16: 1R | I16: 60 | J16: =K16*1.5 -> 18 | K16: =I16/5 -> 12 | N16: 3/Arco Lungo
A17: THAC0 - Tiro = CA Colpita | E17: Arrampicarsi | H17: 1R | I17: 10 | J17: =K17*1.5 -> 3 | K17: =I17/5 -> 2 | N17: 0/Vestiti, Cintura, Stivali
A18: 1R = 10 Sec. | 1T = 10 Min. | E18: Nuotare | H18: 1R | I18: 10 | J18: =K18*1.5 -> 3 | K18: =I18/5 -> 2 | N18: 2/Ascia da Battaglia +1
E19: Giornaliero | H19: 1G | I19: 12 mi | J19: 19km | N19: 2/Scudo +1
A20: Freccie | N20: 1/Faretra
A21: Quadrelli | E21: ='Cleric A'!E21 -> Carica, Ritirata difensiva, Difesa totale
A22: Pietre | E22: ='Cleric A'!E22 -> Spinta, Disarmo, Parare (F), Colpo potente (F) | O22: Slot | P22: 12
A23: Dardi | E23: ='Cleric A'!E23 -> Afferrrare, Liberarsi da presa, Azione Pronta
A24: Giavellotti | E24: ='Cleric A'!E24 -> Attraversare alleati ©, Passare posizione © , | O24: Banca | P24: Trasportati
A25: Olio | E25: ='Cleric A'!E25 -> Azione pronta, Preparare per carica | N25: pp
A26: Acqua Santa | E26: ='Cleric A'!E26 -> Prone: +2 TxC nemici, metà mov per alzarsi | N26: mo | P26: 500
A27: Torce | E27: ='Cleric A'!E27 -> Copertura: Parziale -2 TxC | Totale -4 TxC | N27: ma
E28: ='Cleric A'!E28 -> Tiro oltre 1* alleato: -2 TxC, 1 Colpito Alleato | N28: mr
E29: ='Cleric A'!E29 -> Distanza: corta +1, lunga -1 | O29: Slot | P29: 5
E30: ='Cleric A'!E30 -> Copertura vs area: Parz. +2 TS, Quasi tot. +4 TS
A31: Combinazioni | C31: CA
A32: Ascia/pugnale + Scudo | C32: 0 | N32: Abilità
A33: Ascia due mani | C33: 2 | N33: 1/6 trovare porte segrete
A34: Arco lungo | C34: 2 | N34: 1/6 Ascoltare rumori
A35: Pugnale | C35: 2 | N35: 1/6 ascoltare attr. Porte
L36: THAC0
A37: Arma | B37: Range | C37: AC 9 | D37: 8 | E37: =D37-1 -> 7 | F37: =E37-1 -> 6 | G37: =F37-1 -> 5 | H37: =G37-1 -> 4 | I37: =H37-1 -> 3 | J37: =I37-1 -> 2 | K37: =J37-1 -> 1 | L37: =K37-1 -> 0 | M37: Danno | O37: Note
A38: Ascia da B. | B38: melee lenta | C38: 5 | D38: =C38+1 -> 6 | E38: =D38+1 -> 7 | F38: =E38+1 -> 8 | G38: =F38+1 -> 9 | H38: =G38+1 -> 10 | I38: =H38+1 -> 11 | J38: =I38+1 -> 12 | K38: =J38+1 -> 13 | L38: =K38+1 -> 14 | M38: 1d8+3 | O38: 1 mano 1d6+3
A39: Pugnale | B39: melee | C39: 6 | D39: =C39+1 -> 7 | E39: =D39+1 -> 8 | F39: =E39+1 -> 9 | G39: =F39+1 -> 10 | H39: =G39+1 -> 11 | I39: =H39+1 -> 12 | J39: =I39+1 -> 13 | K39: =J39+1 -> 14 | L39: =K39+1 -> 15 | M39: 1d4+2 | O39: lanciabile 10/20/30'
A40: Arco Lungo | B40: 70/140/210' | C40: 7 | D40: =C40+1 -> 8 | E40: =D40+1 -> 9 | F40: =E40+1 -> 10 | G40: =F40+1 -> 11 | H40: =G40+1 -> 12 | I40: =H40+1 -> 13 | J40: =I40+1 -> 14 | K40: =J40+1 -> 15 | L40: =K40+1 -> 16 | M40: 1d6 | O40: 12 freccie

Sheet Cleric A
A1: Giocatore | B1: Sutan Ambermoor | G1: Corazzato Lento Curatore | K1: Esperienza | N1: 30.000
A2: Razza | B2: Umano | E2: Classe | G2: Chierico | I2: 6° | K2: Allineamento | N2: Neutrale
A4: CA | B4: 2 | E4: Slot | F4: 20 | G4: +6 | L4: Iniziativa | M4: -1 | O4: PF | P4: 31
A5: Abilità | J5: Mod. | M5: Tiri salvezza
A6: 12 | B6: FOR | C6: Apre porte bloccate con 1-2 su 1d6 | J6: 0 | M6: Veleno, Raggio della Morte, +1 mg | P6: 9
A7: 6 | B7: DES | C7: Penalità a attacchi a distanza -1, CA +1, iniziativa -1 | J7: -1 | M7: Bacchetta | P7: 9
A8: 12 | B8: COS | C8: Nessun modificatore | J8: 0 | M8: Pietrificazione Paralisi | P8: 11
A9: 7 | B9: INT | C9: Sa scrivere parole semplici | J9: -1 | M9: Soffio Drago | P9: 14
A10: 13 | B10: SAG | C10: +1 ai TS contro magia | J10: 1 | M10: Incantesimi Bastone Magico | P10: 11
A11: 9 | B11: CAR | C11: Reazioni PNG +0, massimo 4 seguaci, morale seguaci 7 | J11: 0
A13: Lingue Parlate | E13: Movimento | I13: Piedi | J13: Metri | K13: Quad. | N13: Slot/Equipaggiamento
A14: Common, Nanco, Gnomesco, Koboldo,Goblin | E14: Combattimento | H14: 1R | I14: 20 | J14: =K14*1.5 -> 6 | K14: =I14/5 -> 4 | N14: 3/Armatura a piastre
E15: Esplorazione | H15: 1T | I15: 60 | J15: =K15*1.5 -> 18 | K15: =I15/5 -> 12 | N15: 1/Mazza
E16: Correre | H16: 1R | I16: 60 | J16: =K16*1.5 -> 18 | K16: =I16/5 -> 12 | N16: 1/Fionda
A17: THAC0 - Tiro = CA Colpita | E17: Arrampicarsi | H17: 1R | I17: 10 | J17: =K17*1.5 -> 3 | K17: =I17/5 -> 2 | N17: 0/Vestiti, Cintura, Stivali
A18: 1R = 10 Sec. | 1T = 10 Min. | E18: Nuotare | H18: 1R | I18: 10 | J18: =K18*1.5 -> 3 | K18: =I18/5 -> 2 | N18: 0/Simbolo sacro
E19: Giornaliero | H19: 1G | I19: 12mi | J19: 19km | N19: 1/Fiale Acqua santa (2)
A20: Freccie | N20: 2/Scudo +1
A21: Quadrelli | E21: Carica, Ritirata difensiva, Difesa totale
A22: Pietre | E22: Spinta, Disarmo, Parare (F), Colpo potente (F) | O22: Slot | P22: 8
A23: Dardi | E23: Afferrrare, Liberarsi da presa, Azione Pronta
A24: Giavellotti | E24: Attraversare alleati ©, Passare posizione © , | O24: Banca | P24: Trasportati
A25: Olio | E25: Azione pronta, Preparare per carica | N25: pp
A26: Acqua Santa | E26: Prone: +2 TxC nemici, metà mov per alzarsi | N26: mo | P26: 500
A27: Torce | E27: Copertura: Parziale -2 TxC | Totale -4 TxC | N27: ma
E28: Tiro oltre 1* alleato: -2 TxC, 1 Colpito Alleato | N28: mr
E29: Distanza: corta +1, lunga -1 | O29: Slot | P29: 5
E30: Copertura vs area: Parz. +2 TS, Quasi tot. +4 TS
A31: Incantesimi Scelti | C31: 1°/2 | E31: 2°/2 | G31: 3°/1 | I31: 4°/1 | N31: Abilità
A32: 1 Livello | B32: Cura Ferite Leggere 1d6+1, Protezione dal Male -1TxC 12T | N32: 1/6 trovare porte segrete
A33: 2 Livello | B33: Benedizione +1TxC 6R, Trovare Trap./Segr. 2T 30' | N33: 1/6 Ascoltare rumori
A34: 3 Livello | B34: Arma Potenziata +1d6 1T | N34: 1/6 ascoltare attr. Porte
A35: 4 Livello | B35: Cura Ferite Gravi 2d6+2 | N35: Scacciare 2d6
L36: THAC0
A37: Arma | B37: Range | C37: AC 9 | D37: 8 | E37: =D37-1 -> 7 | F37: =E37-1 -> 6 | G37: =F37-1 -> 5 | H37: =G37-1 -> 4 | I37: =H37-1 -> 3 | J37: =I37-1 -> 2 | K37: =J37-1 -> 1 | L37: =K37-1 -> 0 | M37: Danno | O37: Note
A38: Mazza | B38: melee | C38: 8 | D38: =C38+1 -> 9 | E38: =D38+1 -> 10 | F38: =E38+1 -> 11 | G38: =F38+1 -> 12 | H38: =G38+1 -> 13 | I38: =H38+1 -> 14 | J38: =I38+1 -> 15 | K38: =J38+1 -> 16 | L38: =K38+1 -> 17 | M38: 1d6
A39: Fionda | B39: 40/80/160' | C39: 8 | D39: =C39+1 -> 9 | E39: =D39+1 -> 10 | F39: =E39+1 -> 11 | G39: =F39+1 -> 12 | H39: =G39+1 -> 13 | I39: =H39+1 -> 14 | J39: =I39+1 -> 15 | K39: =J39+1 -> 16 | L39: =K39+1 -> 17 | M39: 1d4 | O39: 20 Pietre
A40: Acqua Santa | B40: 10/30/50' | C40: 9 | D40: =C40+1 -> 10 | E40: =D40+1 -> 11 | F40: =E40+1 -> 12 | G40: =F40+1 -> 13 | H40: =G40+1 -> 14 | I40: =H40+1 -> 15 | J40: =I40+1 -> 16 | K40: =J40+1 -> 17 | L40: =K40+1 -> 18 | M40: 1d8 | O40: Lancio, 2R Danni

Sheet Oggetti
A1: Slot Totali | E1: Sovraccarico | I1: Slot Bonus | M1: Slot Occupati
A2: Oggetto | H2: Qt. | I2: Slot | J2: Note/Cariche
A3: 1
A4: =A3+1 -> 2
A5: =A4+1 -> 3
A6: =A5+1 -> 4
A7: =A6+1 -> 5
A8: =A7+1 -> 6
A9: =A8+1 -> 7
A10: =A9+1 -> 8
A11: =A10+1 -> 9
A12: =A11+1 -> 10
A13: =A12+1 -> 11
A14: =A13+1 -> 12
A15: =A14+1 -> 13
... A22: =A21+1 -> 20
Q23: by Maru
A24: THAC0 | C24: CA | D24: CA | E24: CA | F24: CA | G24: CA | H24: CA | I24: CA | J24: CA | K24: CA | L24: CA | M24: CA | N24: CA | O24: CA | P24: CA | Q24: CA
C25: -3 | D25: =C25+1 -> -2 | E25: =D25+1 -> -1 | F25: =E25+1 -> 0 | G25: =F25+1 -> 1 | H25: =G25+1 -> 2 | I25: =H25+1 -> 3 | J25: =I25+1 -> 4 | K25: =J25+1 -> 5 | ... Q25: =P25+1 -> 11
A26: 19 | C26: =$A26-C$25 -> 22 | D26: =$A26-D$25 -> 21 | E26: =$A26-E$25 -> 20 | F26: =$A26-F$25 -> 19 | G26: =$A26-G$25 -> 18 | H26: =$A26-H$25 -> 17 | I26: =$A26-I$25 -> 16 | J26: =$A26-J$25 -> 15 | ... Q26: =$A26-Q$25 -> 8
A27: 18 | C27: =$A27-C$25 -> 21 | D27: =$A27-D$25 -> 20 | E27: =$A27-E$25 -> 19 | F27: =$A27-F$25 -> 18 | G27: =$A27-G$25 -> 17 | H27: =$A27-H$25 -> 16 | I27: =$A27-I$25 -> 15 | J27: =$A27-J$25 -> 14 | ... Q27: =$A27-Q$25 -> 7
A28: 17 | C28: =$A28-C$25 -> 20 | D28: =$A28-D$25 -> 19 | E28: =$A28-E$25 -> 18 | F28: =$A28-F$25 -> 17 | G28: =$A28-G$25 -> 16 | H28: =$A28-H$25 -> 15 | I28: =$A28-I$25 -> 14 | J28: =$A28-J$25 -> 13 | ... Q28: =$A28-Q$25 -> 6
A29: 16 | C29: =$A29-C$25 -> 19 | D29: =$A29-D$25 -> 18 | E29: =$A29-E$25 -> 17 | F29: =$A29-F$25 -> 16 | G29: =$A29-G$25 -> 15 | H29: =$A29-H$25 -> 14 | I29: =$A29-I$25 -> 13 | J29: =$A29-J$25 -> 12 | ... Q29: =$A29-Q$25 -> 5
A30: 15 | C30: =$A30-C$25 -> 18 | D30: =$A30-D$25 -> 17 | E30: =$A30-E$25 -> 16 | F30: =$A30-F$25 -> 15 | G30: =$A30-G$25 -> 14 | H30: =$A30-H$25 -> 13 | I30: =$A30-I$25 -> 12 | J30: =$A30-J$25 -> 11 | ... Q30: =$A30-Q$25 -> 4
A31: 14 | C31: =$A31-C$25 -> 17 | D31: =$A31-D$25 -> 16 | E31: =$A31-E$25 -> 15 | F31: =$A31-F$25 -> 14 | G31: =$A31-G$25 -> 13 | H31: =$A31-H$25 -> 12 | I31: =$A31-I$25 -> 11 | J31: =$A31-J$25 -> 10 | ... Q31: =$A31-Q$25 -> 3
A32: 13 | C32: =$A32-C$25 -> 16 | D32: =$A32-D$25 -> 15 | E32: =$A32-E$25 -> 14 | F32: =$A32-F$25 -> 13 | G32: =$A32-G$25 -> 12 | H32: =$A32-H$25 -> 11 | I32: =$A32-I$25 -> 10 | J32: =$A32-J$25 -> 9 | ... Q32: =$A32-Q$25 -> 2
A33: 12 | C33: =$A33-C$25 -> 15 | D33: =$A33-D$25 -> 14 | E33: =$A33-E$25 -> 13 | F33: =$A33-F$25 -> 12 | G33: =$A33-G$25 -> 11 | H33: =$A33-H$25 -> 10 | I33: =$A33-I$25 -> 9 | J33: =$A33-J$25 -> 8 | ... Q33: =$A33-Q$25 -> 1
A34: 11 | C34: =$A34-C$25 -> 14 | D34: =$A34-D$25 -> 13 | E34: =$A34-E$25 -> 12 | F34: =$A34-F$25 -> 11 | G34: =$A34-G$25 -> 10 | H34: =$A34-H$25 -> 9 | I34: =$A34-I$25 -> 8 | J34: =$A34-J$25 -> 7 | ... Q34: =$A34-Q$25 -> 0
A36: Slot | B36: Esempio | K36: Armatura | M36: CA | N36: Slot | O36: U/E | P36: N | Q36: H
A37: 0 | B37: Anelli, amuleti, pergamene (10), chiavi, gemme | K37: Nessuna | M37: 9 | N37: 0 | O37: 40' | P37: 20' | Q37: 30'
A38: 1 | B38: Armi piccole, torce, pozioni, corda, faretra, acqua s., bacchette | K38: Cuoio | M38: 7 | N38: 2 | O38: 40' | P38: 20' | Q38: 30'
A39: 2 | B39: Armi m., armature l., scudo , arco c., balestra l., stivali, mantello | K39: Cuoio Borchiato | M39: 6 | N39: 2 | O39: 40' | P39: 20' | Q39: 30'
A40: 3 | B40: Armi grandi, armatura pesante, scudo grande, arco l., balestra p. | K40: Cotta di maglie | M40: 5 | N40: 2 | O40: Lancio, 2R Danni | P40: 20' | Q40: 20'
A41: - | B41: Ogni 100 mo 1 Slot, Borsa Conservante +5 slot, fiale 1 slot ogni 5 | K41: Arm. a Scaglie | M41: 6 | N41: 3 | O41: 20' | P41: 20' | Q41: -
K42: Arm. a bande | M42: 4 | N42: 3 | O42: 20' | P42: 20' | Q42: -
A43: TS: tiro ≥ valore = successo | F43: Carica: +2 TxC, -2 CA | K43: Arm. a Piastre | M43: 3 | N43: 3 | O43: 20' | P43: 20' | Q43: -
A44: Torcia 30'/6□, Lanterna 30'/6□, -2 TxC luce fioca, -4 TxC buio | K44: Scudo | M44: -1 | N44: 2
A45: Ritirata difensiva: ½ mov., no attacco opportunità
A46: Copertura vs area: Parz. +2 TS, Quasi tot. +4 TS
A47: Copertura: Parz. -2 TxC, Quasi tot. -4 TxC nemico
...
